<?xml version="1.0"?>
<robot xmlns:xacro="http://ros.org/wiki/xacro">

  <xacro:include filename="02_inertia_macro.xacro"/>
  

  <link name="base_link" />

  <!-- Chassis -->
  <link name="chassis">
    <collision>
      <origin xyz="0 0 0" rpy="0 0 0" />
      <geometry>
        <box size="${base_lx} ${base_ly} ${base_lz}" />
      </geometry>
    </collision>

    <visual>
      <origin xyz="0 0 0" rpy="0 0 0" />
      <geometry>
        <box size="${base_lx} ${base_ly} ${base_lz}" />
      </geometry>
      <material name="Orange" />
    </visual>
    
    <inertial>
      <origin xyz="0 0 0" rpy="0 0 0" />
      <mass value="${base_mass}"/>
      <xacro:box_inertia mass="${base_mass}" width="${base_ly}" height="${base_lz}" depth="${base_lx}"/>
    </inertial>
  </link>

  <joint name="chassis_joint" type="fixed">
    <origin xyz="0 0 -${wheel_radius}" rpy="0 0 0" />
    <parent link="base_link" />
    <child link="chassis" />
  </joint>

  <link name="virtual_rear_wheel">
      <visual>
        <origin xyz="0 0 0" rpy="${PI/2} 0 ${PI/2}"/>
        <geometry>
          <cylinder length="0.01" radius="${wheel_radius}"/>
        </geometry>
        <material name="Invisible"/>
      </visual>
      <inertial>
        <origin xyz="0 0 0" rpy="0 0 0" />
        <mass value="0.005" />
        <inertia ixx="0.001" ixy="0.0" ixz="0.0" iyy="0.001" iyz="0.0" izz="0.001" />
      </inertial>
  </link>

  <joint name="virtual_rear_wheel_joint" type="continuous">
      <parent link="chassis"/>
      <child link="virtual_rear_wheel"/>
      <origin xyz="-${base_lx/2} 0 -${base_lz/2}" rpy="0 0 ${PI/2}"/>
      <axis xyz="1 0 0"/>
      <limit effort="100.0" velocity="100.0"/>
      <dynamics damping="0.02"/>
  </joint>

  <!-- right wheel Link -->
  <link name="rear_right_wheel">
    <collision>
      <geometry>
        <cylinder length="${wheel_len}" radius="${wheel_radius}" /> 
      </geometry>
      <origin xyz="0 0 0" rpy="${PI/2} 0 ${PI/2}"/>
    </collision>
    <visual>
      <origin xyz="0 0 0" rpy="${PI/2} 0 ${PI/2}"/>
      <geometry>
        <cylinder length="${wheel_len}" radius="${wheel_radius}" /> 
      </geometry>
      <material name="Black" />
    </visual>
    <inertial>
      <origin xyz="0 0 0" rpy="${PI/2} 0 ${PI/2}"/>
      <mass value="${wheel_mass}" />
      <xacro:cylinder_inertia mass="${wheel_mass}" radius="${wheel_radius}" height="${wheel_len}"/>
    </inertial>
  </link>

  <joint name="rear_right_wheel_joint" type="continuous">
    <origin xyz="-${base_lx/2} ${base_ly/2} ${base_lz/2}" rpy="0 0 ${PI/2}" />
    <parent link="chassis" />
    <child link="rear_right_wheel" />
    <axis xyz="1 0 0" />
    <dynamics damping="0.02" />
    <limit effort="100.0" velocity="100.0"/>
    <mimic joint="virtual_rear_wheel_joint" multiplier="1.0" offset="0.0"/>
  </joint>


  <!-- left wheel Link -->
  <link name="rear_left_wheel">
    <collision>
      <geometry>
        <cylinder length="${wheel_len}" radius="${wheel_radius}" /> 
      </geometry>
      <origin xyz="0 0 0" rpy="${PI/2} 0 ${PI/2}"/>
    </collision>
    <visual>
      <origin xyz="0 0 0" rpy="${PI/2} 0 ${PI/2}"/>
      <geometry>
        <cylinder length="${wheel_len}" radius="${wheel_radius}" /> 
      </geometry>
      <material name="Black" />
    </visual>
    <inertial>
      <origin xyz="0 0 0" rpy="${PI/2} 0 ${PI/2}"/>
      <mass value="${wheel_mass}" />
      <xacro:cylinder_inertia mass="${wheel_mass}" radius="${wheel_radius}" height="${wheel_len}"/>
    </inertial>
  </link>

  <joint name="rear_left_wheel_joint" type="continuous">
    <origin xyz="-${base_lx/2} -${base_ly/2} ${base_lz/2}" rpy="0 0 ${PI/2}" />
    <parent link="chassis" />
    <child link="rear_left_wheel" />
    <axis xyz="1 0 0" />
    <dynamics damping="0.02" />
    <limit effort="100.0" velocity="100.0"/>
    <mimic joint="virtual_rear_wheel_joint" multiplier="1.0" offset="0.0"/>
  </joint>


  <link name="virtual_front_wheel">
    <visual>
      <origin xyz="0 0 0" rpy="${PI/2} 0 ${PI/2}"/>
      <geometry>
        <cylinder length="0.01" radius="${wheel_radius}"/>
      </geometry>
      <material name="Invisible"/>
    </visual>
      <inertial>
        <origin xyz="0 0 0" rpy="0 0 0" />
        <mass value="0.005" />
        <inertia ixx="0.001" ixy="0.0" ixz="0.0" iyy="0.001" iyz="0.0" izz="0.001" />
      </inertial>
  </link>

  <joint name="virtual_front_wheel_joint" type="revolute">
    <parent link="chassis"/>
    <child link="virtual_front_wheel"/>
    <origin xyz="${base_lx/2} 0 -${base_lz/2}" rpy="0 0 ${PI/2}"/>
    <axis xyz="0 0 1"/>
    <limit lower="-0.8" upper="0.8" effort="100.0" velocity="0.0"/>
    <dynamics damping="0.02"/>
  </joint>

 <!-- right wheel Link -->
  <link name="front_right_wheel">
    <collision>
      <origin xyz="0 0 0" rpy="${PI/2} 0 ${PI/2}"/>
      <geometry>
        <cylinder length="${wheel_len}" radius="${wheel_radius}" />
      </geometry>
    </collision>
    <visual>
     <origin xyz="0 0 0" rpy="${PI/2} 0 ${PI/2}"/>
      <geometry>
        <cylinder length="${wheel_len}" radius="${wheel_radius}" />
      </geometry>
      <material name="Black" />
    </visual>

    <inertial>
      <origin xyz="0 0 0" rpy="${PI/2} 0 ${PI/2}"/>
      <mass value="${wheel_mass}" />
      <xacro:cylinder_inertia mass="${wheel_mass}" radius="${wheel_radius}" height="${wheel_len*4}"/>
    </inertial>
  </link>

  <joint name="front_right_wheel_joint" type="revolute">
    <parent link="chassis" />
    <child link="front_right_wheel" />
    <origin xyz="${base_lx/2} ${base_ly/2} -${base_lz/2}" rpy="0 0 ${PI/2}"/>
    <axis xyz="0 0 1"/>
    <limit lower="-0.8" upper="0.8" effort="100.0" velocity="0.0"/>
    <dynamics damping="0.02"/>
    <mimic joint="virtual_front_wheel_joint" multiplier="1.0" offset="0.0"/>
  </joint>

 <!-- left wheel Link -->
  <link name="front_left_wheel">
    <collision>
    <origin xyz="0 0 0" rpy="${PI/2} 0 ${PI/2}"/>
      <geometry>
        <cylinder length="${wheel_len}" radius="${wheel_radius}" />
      </geometry>
    </collision>
    <visual>
     <origin xyz="0 0 0" rpy="${PI/2} 0 ${PI/2}"/>
      <geometry>
        <cylinder length="${wheel_len}" radius="${wheel_radius}" />
      </geometry>
      <material name="Black" />
    </visual>

    <inertial>
      <origin xyz="0 0 0" rpy="${PI/2} 0 ${PI/2}"/>
      <mass value="${wheel_mass}" />
      <xacro:cylinder_inertia mass="${wheel_mass}" radius="${wheel_radius}" height="${wheel_len*4}"/>
    </inertial>
  </link>

  <joint name="front_left_wheel_joint" type="revolute">
    <parent link="chassis" />
    <child link="front_left_wheel" />
    <origin xyz="${base_lx/2} -${base_ly/2} -${base_lz/2}" rpy="0 0 ${PI/2}"/>
    <axis xyz="0 0 1"/>
    <limit lower="-0.8" upper="0.8" effort="100.0" velocity="0.0"/>
    <dynamics damping="0.02"/>
    <mimic joint="virtual_front_wheel_joint" multiplier="1.0" offset="0.0"/>
  </joint>


</robot>
